Workbook

Sheet Difference
B2: Comparison of Values (S2*2 +S1) | J2: Analysis of differences:
B3: =IF(OR(Scorer_2!G2="", Scorer_1!G2=""), NA(), Scorer_2!G2*2 + Scorer_1!G2) -> 0 | C3: =IF(OR(Scorer_2!H2="", Scorer_1!H2=""), NA(), Scorer_2!H2*2 + Scorer_1!H2) -> 0 | D3: =IF(OR(Scorer_2!I2="", Scorer_1!I2=""), NA(), Scorer_2!I2*2 + Scorer_1!I2) -> 0 | E3: =IF(OR(Scorer_2!J2="", Scorer_1!J2=""), NA(), Scorer_2!J2*2 + Scorer_1!J2) -> 0 | F3: =IF(OR(Scorer_2!K2="", Scorer_1!K2=""), NA(), Scorer_2!K2*2 + Scorer_1!K2) -> 1 | G3: =IF(OR(Scorer_2!L2="", Scorer_1!L2=""), NA(), Scorer_2!L2*2 + Scorer_1!L2) -> 1 | J3: Value | K3: Meaning | L3: Count | M3: Percentage
B4: =IF(OR(Scorer_2!G3="", Scorer_1!G3=""), NA(), Scorer_2!G3*2 + Scorer_1!G3) -> 0 | C4: =IF(OR(Scorer_2!H3="", Scorer_1!H3=""), NA(), Scorer_2!H3*2 + Scorer_1!H3) -> 0 | D4: =IF(OR(Scorer_2!I3="", Scorer_1!I3=""), NA(), Scorer_2!I3*2 + Scorer_1!I3) -> 0 | E4: =IF(OR(Scorer_2!J3="", Scorer_1!J3=""), NA(), Scorer_2!J3*2 + Scorer_1!J3) -> 0 | F4: =IF(OR(Scorer_2!K3="", Scorer_1!K3=""), NA(), Scorer_2!K3*2 + Scorer_1!K3) -> 0 | G4: =IF(OR(Scorer_2!L3="", Scorer_1!L3=""), NA(), Scorer_2!L3*2 + Scorer_1!L3) -> 0 | J4: 0 | K4: Both no | L4: =COUNTIF(B3:G627,0) -> 2873 | M4: =L4/L8 -> 0.89669164
B5: =IF(OR(Scorer_2!G4="", Scorer_1!G4=""), NA(), Scorer_2!G4*2 + Scorer_1!G4) -> 0 | C5: =IF(OR(Scorer_2!H4="", Scorer_1!H4=""), NA(), Scorer_2!H4*2 + Scorer_1!H4) -> 0 | D5: =IF(OR(Scorer_2!I4="", Scorer_1!I4=""), NA(), Scorer_2!I4*2 + Scorer_1!I4) -> 2 | E5: =IF(OR(Scorer_2!J4="", Scorer_1!J4=""), NA(), Scorer_2!J4*2 + Scorer_1!J4) -> 3 | F5: =IF(OR(Scorer_2!K4="", Scorer_1!K4=""), NA(), Scorer_2!K4*2 + Scorer_1!K4) -> 0 | G5: =IF(OR(Scorer_2!L4="", Scorer_1!L4=""), NA(), Scorer_2!L4*2 + Scorer_1!L4) -> 0 | J5: 1 | K5: S2 no, S1 yes | L5: =COUNTIF(B3:G627,1) -> 142 | M5: =L5/L8 -> 0.0443196
B6: =IF(OR(Scorer_2!G5="", Scorer_1!G5=""), NA(), Scorer_2!G5*2 + Scorer_1!G5) -> 0 | C6: =IF(OR(Scorer_2!H5="", Scorer_1!H5=""), NA(), Scorer_2!H5*2 + Scorer_1!H5) -> 0 | D6: =IF(OR(Scorer_2!I5="", Scorer_1!I5=""), NA(), Scorer_2!I5*2 + Scorer_1!I5) -> 0 | E6: =IF(OR(Scorer_2!J5="", Scorer_1!J5=""), NA(), Scorer_2!J5*2 + Scorer_1!J5) -> 1 | F6: =IF(OR(Scorer_2!K5="", Scorer_1!K5=""), NA(), Scorer_2!K5*2 + Scorer_1!K5) -> 0 | G6: =IF(OR(Scorer_2!L5="", Scorer_1!L5=""), NA(), Scorer_2!L5*2 + Scorer_1!L5) -> 0 | J6: 2 | K6: S2 yes, S1 no | L6: =COUNTIF(B3:G627,2) -> 117 | M6: =L6/L8 -> 0.036516854
B7: =IF(OR(Scorer_2!G6="", Scorer_1!G6=""), NA(), Scorer_2!G6*2 + Scorer_1!G6) -> 0 | C7: =IF(OR(Scorer_2!H6="", Scorer_1!H6=""), NA(), Scorer_2!H6*2 + Scorer_1!H6) -> 2 | D7: =IF(OR(Scorer_2!I6="", Scorer_1!I6=""), NA(), Scorer_2!I6*2 + Scorer_1!I6) -> 0 | E7: =IF(OR(Scorer_2!J6="", Scorer_1!J6=""), NA(), Scorer_2!J6*2 + Scorer_1!J6) -> 0 | F7: =IF(OR(Scorer_2!K6="", Scorer_1!K6=""), NA(), Scorer_2!K6*2 + Scorer_1!K6) -> 0 | G7: =IF(OR(Scorer_2!L6="", Scorer_1!L6=""), NA(), Scorer_2!L6*2 + Scorer_1!L6) -> 0 | J7: 3 | K7: Both yes | L7: =COUNTIF(B3:G627,3) -> 72 | M7: =L7/L8 -> 0.02247191
B8: =IF(OR(Scorer_2!G7="", Scorer_1!G7=""), NA(), Scorer_2!G7*2 + Scorer_1!G7) -> 0 | C8: =IF(OR(Scorer_2!H7="", Scorer_1!H7=""), NA(), Scorer_2!H7*2 + Scorer_1!H7) -> 0 | D8: =IF(OR(Scorer_2!I7="", Scorer_1!I7=""), NA(), Scorer_2!I7*2 + Scorer_1!I7) -> 2 | E8: =IF(OR(Scorer_2!J7="", Scorer_1!J7=""), NA(), Scorer_2!J7*2 + Scorer_1!J7) -> 0 | F8: =IF(OR(Scorer_2!K7="", Scorer_1!K7=""), NA(), Scorer_2!K7*2 + Scorer_1!K7) -> 3 | G8: =IF(OR(Scorer_2!L7="", Scorer_1!L7=""), NA(), Scorer_2!L7*2 + Scorer_1!L7) -> 2 | J8: SUM: | L8: =SUM(L4:L7) -> 3204 | M8: =SUM(M4:M7) -> 1
B9: =IF(OR(Scorer_2!G8="", Scorer_1!G8=""), NA(), Scorer_2!G8*2 + Scorer_1!G8) -> 0 | C9: =IF(OR(Scorer_2!H8="", Scorer_1!H8=""), NA(), Scorer_2!H8*2 + Scorer_1!H8) -> 0 | D9: =IF(OR(Scorer_2!I8="", Scorer_1!I8=""), NA(), Scorer_2!I8*2 + Scorer_1!I8) -> 0 | E9: =IF(OR(Scorer_2!J8="", Scorer_1!J8=""), NA(), Scorer_2!J8*2 + Scorer_1!J8) -> 1 | F9: =IF(OR(Scorer_2!K8="", Scorer_1!K8=""), NA(), Scorer_2!K8*2 + Scorer_1!K8) -> 0 | G9: =IF(OR(Scorer_2!L8="", Scorer_1!L8=""), NA(), Scorer_2!L8*2 + Scorer_1!L8) -> 0
B10: =IF(OR(Scorer_2!G9="", Scorer_1!G9=""), NA(), Scorer_2!G9*2 + Scorer_1!G9) -> 0 | C10: =IF(OR(Scorer_2!H9="", Scorer_1!H9=""), NA(), Scorer_2!H9*2 + Scorer_1!H9) -> 0 | D10: =IF(OR(Scorer_2!I9="", Scorer_1!I9=""), NA(), Scorer_2!I9*2 + Scorer_1!I9) -> 0 | E10: =IF(OR(Scorer_2!J9="", Scorer_1!J9=""), NA(), Scorer_2!J9*2 + Scorer_1!J9) -> 0 | F10: =IF(OR(Scorer_2!K9="", Scorer_1!K9=""), NA(), Scorer_2!K9*2 + Scorer_1!K9) -> 0 | G10: =IF(OR(Scorer_2!L9="", Scorer_1!L9=""), NA(), Scorer_2!L9*2 + Scorer_1!L9) -> 0
B11: =IF(OR(Scorer_2!G10="", Scorer_1!G10=""), NA(), Scorer_2!G10*2 + Scorer_1!G10) -> 0 | C11: =IF(OR(Scorer_2!H10="", Scorer_1!H10=""), NA(), Scorer_2!H10*2 + Scorer_1!H10) -> 0 | D11: =IF(OR(Scorer_2!I10="", Scorer_1!I10=""), NA(), Scorer_2!I10*2 + Scorer_1!I10) -> 1 | E11: =IF(OR(Scorer_2!J10="", Scorer_1!J10=""), NA(), Scorer_2!J10*2 + Scorer_1!J10) -> 3 | F11: =IF(OR(Scorer_2!K10="", Scorer_1!K10=""), NA(), Scorer_2!K10*2 + Scorer_1!K10) -> 0 | G11: =IF(OR(Scorer_2!L10="", Scorer_1!L10=""), NA(), Scorer_2!L10*2 + Scorer_1!L10) -> 2 | J11: Interpretation: For the sample of Jacobson-style trials scored, Scorer 1 and Scorer 2 agree on 91.92% of trials (2945/3204).
B12: =IF(OR(Scorer_2!G11="", Scorer_1!G11=""), NA(), Scorer_2!G11*2 + Scorer_1!G11) -> 0 | C12: =IF(OR(Scorer_2!H11="", Scorer_1!H11=""), NA(), Scorer_2!H11*2 + Scorer_1!H11) -> 0 | D12: =IF(OR(Scorer_2!I11="", Scorer_1!I11=""), NA(), Scorer_2!I11*2 + Scorer_1!I11) -> 0 | E12: =IF(OR(Scorer_2!J11="", Scorer_1!J11=""), NA(), Scorer_2!J11*2 + Scorer_1!J11) -> 1 | F12: =IF(OR(Scorer_2!K11="", Scorer_1!K11=""), NA(), Scorer_2!K11*2 + Scorer_1!K11) -> 0 | G12: =IF(OR(Scorer_2!L11="", Scorer_1!L11=""), NA(), Scorer_2!L11*2 + Scorer_1!L11) -> 1
B13: =IF(OR(Scorer_2!G12="", Scorer_1!G12=""), NA(), Scorer_2!G12*2 + Scorer_1!G12) -> 0 | C13: =IF(OR(Scorer_2!H12="", Scorer_1!H12=""), NA(), Scorer_2!H12*2 + Scorer_1!H12) -> 0 | D13: =IF(OR(Scorer_2!I12="", Scorer_1!I12=""), NA(), Scorer_2!I12*2 + Scorer_1!I12) -> 0 | E13: =IF(OR(Scorer_2!J12="", Scorer_1!J12=""), NA(), Scorer_2!J12*2 + Scorer_1!J12) -> 0 | F13: =IF(OR(Scorer_2!K12="", Scorer_1!K12=""), NA(), Scorer_2!K12*2 + Scorer_1!K12) -> 0 | G13: =IF(OR(Scorer_2!L12="", Scorer_1!L12=""), NA(), Scorer_2!L12*2 + Scorer_1!L12) -> 0
B14: =IF(OR(Scorer_2!G13="", Scorer_1!G13=""), NA(), Scorer_2!G13*2 + Scorer_1!G13) -> 0 | C14: =IF(OR(Scorer_2!H13="", Scorer_1!H13=""), NA(), Scorer_2!H13*2 + Scorer_1!H13) -> 0 | D14: =IF(OR(Scorer_2!I13="", Scorer_1!I13=""), NA(), Scorer_2!I13*2 + Scorer_1!I13) -> 0 | E14: =IF(OR(Scorer_2!J13="", Scorer_1!J13=""), NA(), Scorer_2!J13*2 + Scorer_1!J13) -> 0 | F14: =IF(OR(Scorer_2!K13="", Scorer_1!K13=""), NA(), Scorer_2!K13*2 + Scorer_1!K13) -> 0 | G14: =IF(OR(Scorer_2!L13="", Scorer_1!L13=""), NA(), Scorer_2!L13*2 + Scorer_1!L13) -> 0
B15: =IF(OR(Scorer_2!G14="", Scorer_1!G14=""), NA(), Scorer_2!G14*2 + Scorer_1!G14) -> 0 | C15: =IF(OR(Scorer_2!H14="", Scorer_1!H14=""), NA(), Scorer_2!H14*2 + Scorer_1!H14) -> 0 | D15: =IF(OR(Scorer_2!I14="", Scorer_1!I14=""), NA(), Scorer_2!I14*2 + Scorer_1!I14) -> 0 | E15: =IF(OR(Scorer_2!J14="", Scorer_1!J14=""), NA(), Scorer_2!J14*2 + Scorer_1!J14) -> 0 | F15: =IF(OR(Scorer_2!K14="", Scorer_1!K14=""), NA(), Scorer_2!K14*2 + Scorer_1!K14) -> 0 | G15: =IF(OR(Scorer_2!L14="", Scorer_1!L14=""), NA(), Scorer_2!L14*2 + Scorer_1!L14) -> 0
B16: =IF(OR(Scorer_2!G15="", Scorer_1!G15=""), NA(), Scorer_2!G15*2 + Scorer_1!G15) -> 0 | C16: =IF(OR(Scorer_2!H15="", Scorer_1!H15=""), NA(), Scorer_2!H15*2 + Scorer_1!H15) -> 0 | D16: =IF(OR(Scorer_2!I15="", Scorer_1!I15=""), NA(), Scorer_2!I15*2 + Scorer_1!I15) -> 0 | E16: =IF(OR(Scorer_2!J15="", Scorer_1!J15=""), NA(), Scorer_2!J15*2 + Scorer_1!J15) -> 0 | F16: =IF(OR(Scorer_2!K15="", Scorer_1!K15=""), NA(), Scorer_2!K15*2 + Scorer_1!K15) -> 0 | G16: =IF(OR(Scorer_2!L15="", Scorer_1!L15=""), NA(), Scorer_2!L15*2 + Scorer_1!L15) -> 0
B17: =IF(OR(Scorer_2!G16="", Scorer_1!G16=""), NA(), Scorer_2!G16*2 + Scorer_1!G16) -> 0 | C17: =IF(OR(Scorer_2!H16="", Scorer_1!H16=""), NA(), Scorer_2!H16*2 + Scorer_1!H16) -> 0 | D17: =IF(OR(Scorer_2!I16="", Scorer_1!I16=""), NA(), Scorer_2!I16*2 + Scorer_1!I16) -> 0 | E17: =IF(OR(Scorer_2!J16="", Scorer_1!J16=""), NA(), Scorer_2!J16*2 + Scorer_1!J16) -> 0 | F17: =IF(OR(Scorer_2!K16="", Scorer_1!K16=""), NA(), Scorer_2!K16*2 + Scorer_1!K16) -> 0 | G17: =IF(OR(Scorer_2!L16="", Scorer_1!L16=""), NA(), Scorer_2!L16*2 + Scorer_1!L16) -> 2
B18: =IF(OR(Scorer_2!G17="", Scorer_1!G17=""), NA(), Scorer_2!G17*2 + Scorer_1!G17) -> 0 | C18: =IF(OR(Scorer_2!H17="", Scorer_1!H17=""), NA(), Scorer_2!H17*2 + Scorer_1!H17) -> 0 | D18: =IF(OR(Scorer_2!I17="", Scorer_1!I17=""), NA(), Scorer_2!I17*2 + Scorer_1!I17) -> 0 | E18: =IF(OR(Scorer_2!J17="", Scorer_1!J17=""), NA(), Scorer_2!J17*2 + Scorer_1!J17) -> 0 | F18: =IF(OR(Scorer_2!K17="", Scorer_1!K17=""), NA(), Scorer_2!K17*2 + Scorer_1!K17) -> 0 | G18: =IF(OR(Scorer_2!L17="", Scorer_1!L17=""), NA(), Scorer_2!L17*2 + Scorer_1!L17) -> 3
B19: =IF(OR(Scorer_2!G18="", Scorer_1!G18=""), NA(), Scorer_2!G18*2 + Scorer_1!G18) -> 0 | C19: =IF(OR(Scorer_2!H18="", Scorer_1!H18=""), NA(), Scorer_2!H18*2 + Scorer_1!H18) -> 0 | D19: =IF(OR(Scorer_2!I18="", Scorer_1!I18=""), NA(), Scorer_2!I18*2 + Scorer_1!I18) -> 3 | E19: =IF(OR(Scorer_2!J18="", Scorer_1!J18=""), NA(), Scorer_2!J18*2 + Scorer_1!J18) -> 0 | F19: =IF(OR(Scorer_2!K18="", Scorer_1!K18=""), NA(), Scorer_2!K18*2 + Scorer_1!K18) -> 0 | G19: =IF(OR(Scorer_2!L18="", Scorer_1!L18=""), NA(), Scorer_2!L18*2 + Scorer_1!L18) -> 2
B20: =IF(OR(Scorer_2!G19="", Scorer_1!G19=""), NA(), Scorer_2!G19*2 + Scorer_1!G19) -> 0 | C20: =IF(OR(Scorer_2!H19="", Scorer_1!H19=""), NA(), Scorer_2!H19*2 + Scorer_1!H19) -> 0 | D20: =IF(OR(Scorer_2!I19="", Scorer_1!I19=""), NA(), Scorer_2!I19*2 + Scorer_1!I19) -> 0 | E20: =IF(OR(Scorer_2!J19="", Scorer_1!J19=""), NA(), Scorer_2!J19*2 + Scorer_1!J19) -> 0 | F20: =IF(OR(Scorer_2!K19="", Scorer_1!K19=""), NA(), Scorer_2!K19*2 + Scorer_1!K19) -> 0 | G20: =IF(OR(Scorer_2!L19="", Scorer_1!L19=""), NA(), Scorer_2!L19*2 + Scorer_1!L19) -> 0
B21: =IF(OR(Scorer_2!G20="", Scorer_1!G20=""), NA(), Scorer_2!G20*2 + Scorer_1!G20) -> 0 | C21: =IF(OR(Scorer_2!H20="", Scorer_1!H20=""), NA(), Scorer_2!H20*2 + Scorer_1!H20) -> 0 | D21: =IF(OR(Scorer_2!I20="", Scorer_1!I20=""), NA(), Scorer_2!I20*2 + Scorer_1!I20) -> 0 | E21: =IF(OR(Scorer_2!J20="", Scorer_1!J20=""), NA(), Scorer_2!J20*2 + Scorer_1!J20) -> 0 | F21: =IF(OR(Scorer_2!K20="", Scorer_1!K20=""), NA(), Scorer_2!K20*2 + Scorer_1!K20) -> 0 | G21: =IF(OR(Scorer_2!L20="", Scorer_1!L20=""), NA(), Scorer_2!L20*2 + Scorer_1!L20) -> 0
B22: =IF(OR(Scorer_2!G21="", Scorer_1!G21=""), NA(), Scorer_2!G21*2 + Scorer_1!G21) -> 0 | C22: =IF(OR(Scorer_2!H21="", Scorer_1!H21=""), NA(), Scorer_2!H21*2 + Scorer_1!H21) -> 0 | D22: =IF(OR(Scorer_2!I21="", Scorer_1!I21=""), NA(), Scorer_2!I21*2 + Scorer_1!I21) -> 0 | E22: =IF(OR(Scorer_2!J21="", Scorer_1!J21=""), NA(), Scorer_2!J21*2 + Scorer_1!J21) -> 0 | F22: =IF(OR(Scorer_2!K21="", Scorer_1!K21=""), NA(), Scorer_2!K21*2 + Scorer_1!K21) -> 0 | G22: =IF(OR(Scorer_2!L21="", Scorer_1!L21=""), NA(), Scorer_2!L21*2 + Scorer_1!L21) -> 0
B23: =IF(OR(Scorer_2!G22="", Scorer_1!G22=""), NA(), Scorer_2!G22*2 + Scorer_1!G22) -> 0 | C23: =IF(OR(Scorer_2!H22="", Scorer_1!H22=""), NA(), Scorer_2!H22*2 + Scorer_1!H22) -> 0 | D23: =IF(OR(Scorer_2!I22="", Scorer_1!I22=""), NA(), Scorer_2!I22*2 + Scorer_1!I22) -> 3 | E23: =IF(OR(Scorer_2!J22="", Scorer_1!J22=""), NA(), Scorer_2!J22*2 + Scorer_1!J22) -> 0 | F23: =IF(OR(Scorer_2!K22="", Scorer_1!K22=""), NA(), Scorer_2!K22*2 + Scorer_1!K22) -> 1 | G23: =IF(OR(Scorer_2!L22="", Scorer_1!L22=""), NA(), Scorer_2!L22*2 + Scorer_1!L22) -> 0
... B627: =IF(OR(Scorer_2!G626="", Scorer_1!G626=""), NA(), Scorer_2!G626*2 + Scorer_1!G626) -> 0 | C627: =IF(OR(Scorer_2!H626="", Scorer_1!H626=""), NA(), Scorer_2!H626*2 + Scorer_1!H626) -> 0 | D627: =IF(OR(Scorer_2!I626="", Scorer_1!I626=""), NA(), Scorer_2!I626*2 + Scorer_1!I626) -> 0 | E627: =IF(OR(Scorer_2!J626="", Scorer_1!J626=""), NA(), Scorer_2!J626*2 + Scorer_1!J626) -> 0 | F627: =IF(OR(Scorer_2!K626="", Scorer_1!K626=""), NA(), Scorer_2!K626*2 + Scorer_1!K626) -> 0 | G627: =IF(OR(Scorer_2!L626="", Scorer_1!L626=""), NA(), Scorer_2!L626*2 + Scorer_1!L626) -> 0

Sheet Scorer_1
A1: Run | B1: group_day | C1: Trough | D1: BlockNum | E1: BlockType | F1: Trial | G1: W1 | H1: W2 | I1: W3 | J1: W4 | K1: W5 | L1: W6
A2: 2025_02_06_09_50_08_trial_1_LO | B2: R1_1 | C2: Milled trough + attached electrodes | D2: 1 | E2: LO | F2: 1 | G2: 0 | H2: 0 | I2: 0 | J2: 0 | K2: 1 | L2: 1
C3: 20 trials | D3: 1 | E3: LO | F3: 2 | G3: 0 | H3: 0 | I3: 0 | J3: 0 | K3: 0 | L3: 0
C4: 20s ITI | D4: 1 | E4: LO | F4: 3 | G4: 0 | H4: 0 | I4: 0 | J4: 1 | K4: 0 | L4: 0
C5: All CRs are turns or contractions | D5: 1 | E5: LO | F5: 4 | G5: 0 | H5: 0 | I5: 0 | J5: 1 | K5: 0 | L5: 0
C6: CC High | D6: 1 | E6: LO | F6: 5 | G6: 0 | H6: 0 | I6: 0 | J6: 0 | K6: 0 | L6: 0
D7: 1 | E7: LO | F7: 6 | G7: 0 | H7: 0 | I7: 0 | J7: 0 | K7: 1 | L7: 0
D8: 1 | E8: LO | F8: 7 | G8: 0 | H8: 0 | I8: 0 | J8: 1 | K8: 0 | L8: 0
D9: 1 | E9: LO | F9: 8 | G9: 0 | H9: 0 | I9: 0 | J9: 0 | K9: 0 | L9: 0
D10: 1 | E10: LO | F10: 9 | G10: 0 | H10: 0 | I10: 1 | J10: 1 | K10: 0 | L10: 0
D11: 1 | E11: LO | F11: 10 | G11: 0 | H11: 0 | I11: 0 | J11: 1 | K11: 0 | L11: 1
D12: 1 | E12: LO | F12: 11 | G12: 0 | H12: 0 | I12: 0 | J12: 0 | K12: 0 | L12: 0
D13: 1 | E13: LO | F13: 12 | G13: 0 | H13: 0 | I13: 0 | J13: 0 | K13: 0 | L13: 0
D14: 1 | E14: LO | F14: 13 | G14: 0 | H14: 0 | I14: 0 | J14: 0 | K14: 0 | L14: 0
D15: 1 | E15: LO | F15: 14 | G15: 0 | H15: 0 | I15: 0 | J15: 0 | K15: 0 | L15: 0
D16: 1 | E16: LO | F16: 15 | G16: 0 | H16: 0 | I16: 0 | J16: 0 | K16: 0 | L16: 0
D17: 1 | E17: LO | F17: 16 | G17: 0 | H17: 0 | I17: 0 | J17: 0 | K17: 0 | L17: 1
D18: 1 | E18: LO | F18: 17 | G18: 0 | H18: 0 | I18: 1 | J18: 0 | K18: 0 | L18: 0
... D26: 1 | E26: LO | F26: 25 | G26: 0 | H26: 0 | I26: 0 | J26: 0 | K26: 0 | L26: 0
A27: 2025_02_06_10_10_21_trial_1_LO | B27: R1_1 | C27: Milled trough + attached electrodes | D27: 2 | E27: LO | F27: 1 | G27: 0 | H27: 0 | I27: 0 | J27: 0 | K27: 1 | L27: 1
C28: 20 trials | D28: 2 | E28: LO | F28: 2 | G28: 0 | H28: 0 | I28: 0 | J28: 0 | K28: 0 | L28: 0
C29: 20s ITI | D29: 2 | E29: LO | F29: 3 | G29: 0 | H29: 0 | I29: 0 | J29: 0 | K29: 1 | L29: 1
C30: All CRs are turns or contractions | D30: 2 | E30: LO | F30: 4 | G30: 0 | H30: 0 | I30: 0 | J30: 0 | K30: 1 | L30: 1
C31: CC High | D31: 2 | E31: LO | F31: 5 | G31: 1 | H31: 0 | I31: 0 | J31: 0 | K31: 0 | L31: 0
D32: 2 | E32: LO | F32: 6 | G32: 0 | H32: 0 | I32: 0 | J32: 0 | K32: 0 | L32: 0
D33: 2 | E33: LO | F33: 7 | G33: 0 | H33: 0 | I33: 0 | J33: 0 | K33: 1 | L33: 0
D34: 2 | E34: LO | F34: 8 | G34: 1 | H34: 0 | I34: 1 | J34: 1 | K34: 0 | L34: 0
D35: 2 | E35: LO | F35: 9 | G35: 0 | H35: 0 | I35: 0 | J35: 0 | K35: 0 | L35: 1
D36: 2 | E36: LO | F36: 10 | G36: 0 | H36: 0 | I36: 0 | J36: 1 | K36: 0 | L36: 0
D37: 2 | E37: LO | F37: 11 | G37: 0 | H37: 0 | I37: 0 | J37: 0 | K37: 0 | L37: 0
D38: 2 | E38: LO | F38: 12 | G38: 0 | H38: 0 | I38: 0 | J38: 0 | K38: 0 | L38: 0
D39: 2 | E39: LO | F39: 13 | G39: 0 | H39: 0 | I39: 0 | J39: 0 | K39: 1 | L39: 0
D40: 2 | E40: LO | F40: 14 | G40: 0 | H40: 0 | I40: 0 | J40: 0 | K40: 0 | L40: 1
D41: 2 | E41: LO | F41: 15 | G41: 0 | H41: 0 | I41: 0 | J41: 0 | K41: 1 | L41: 1
D42: 2 | E42: LO | F42: 16 | G42: 0 | H42: 0 | I42: 0 | J42: 0 | K42: 0 | L42: 0
D43: 2 | E43: LO | F43: 17 | G43: 0 | H43: 0 | I43: 0 | J43: 0 | K43: 0 | L43: 0
... D51: 2 | E51: LO | F51: 25 | G51: 0 | H51: 0 | I51: 0 | J51: 0 | K51: 0 | L51: 0
A52: 2025_02_06_10_31_37_trial_1_CC | B52: R1_1 | C52: Milled trough + attached electrodes | D52: 3 | E52: CC | F52: 1 | G52: 0 | H52: 0 | I52: 0 | J52: 0 | K52: 0 | L52: 0
C53: 20 trials | D53: 3 | E53: CC | F53: 2 | G53: 0 | H53: 0 | I53: 0 | J53: 0 | K53: 1 | L53: 1
C54: 20s ITI | D54: 3 | E54: CC | F54: 3 | G54: 0 | H54: 0 | I54: 0 | J54: 0 | K54: 1 | L54: 0
...

Sheet Scorer_2
A1: Run | B1: group_day | C1: Trough | D1: BlockNum | E1: BlockType | F1: Trial | G1: W1 | H1: W2 | I1: W3 | J1: W4 | K1: W5 | L1: W6
A2: R_Stats_video_Smiling_Flick | F2: 1 | G2: 0 | H2: 0 | I2: 0 | J2: 0 | K2: 0 | L2: 0
F3: 2 | G3: 0 | H3: 0 | I3: 0 | J3: 0 | K3: 0 | L3: 0
F4: 3 | G4: 0 | H4: 0 | I4: 1 | J4: 1 | K4: 0 | L4: 0
F5: 4 | G5: 0 | H5: 0 | I5: 0 | J5: 0 | K5: 0 | L5: 0
F6: 5 | G6: 0 | H6: 1 | I6: 0 | J6: 0 | K6: 0 | L6: 0
F7: 6 | G7: 0 | H7: 0 | I7: 1 | J7: 0 | K7: 1 | L7: 1
F8: 7 | G8: 0 | H8: 0 | I8: 0 | J8: 0 | K8: 0 | L8: 0
F9: 8 | G9: 0 | H9: 0 | I9: 0 | J9: 0 | K9: 0 | L9: 0
F10: 9 | G10: 0 | H10: 0 | I10: 0 | J10: 1 | K10: 0 | L10: 1
F11: 10 | G11: 0 | H11: 0 | I11: 0 | J11: 0 | K11: 0 | L11: 0
F12: 11 | G12: 0 | H12: 0 | I12: 0 | J12: 0 | K12: 0 | L12: 0
F13: 12 | G13: 0 | H13: 0 | I13: 0 | J13: 0 | K13: 0 | L13: 0
F14: 13 | G14: 0 | H14: 0 | I14: 0 | J14: 0 | K14: 0 | L14: 0
... F26: 25 | G26: 0 | H26: 0 | I26: 0 | J26: 0 | K26: 0 | L26: 0
A27: R_Stats_video_Wooden_Chronicle | F27: 1 | G27: 0 | H27: 0 | I27: 0 | J27: 0 | K27: 0 | L27: 1
F28: 2 | G28: 0 | H28: 0 | I28: 0 | J28: 1 | K28: 0 | L28: 0
F29: 3 | G29: 0 | H29: 0 | I29: 0 | J29: 0 | K29: 0 | L29: 1
F30: 4 | G30: 0 | H30: 0 | I30: 0 | J30: 0 | K30: 1 | L30: 0
F31: 5 | G31: 1 | H31: 0 | I31: 0 | J31: 0 | K31: 0 | L31: 0
F32: 6 | G32: 0 | H32: 0 | I32: 0 | J32: 0 | K32: 0 | L32: 0
F33: 7 | G33: 0 | H33: 0 | I33: 0 | J33: 0 | K33: 0 | L33: 0
F34: 8 | G34: 1 | H34: 0 | I34: 1 | J34: 1 | K34: 0 | L34: 0
F35: 9 | G35: 0 | H35: 0 | I35: 1 | J35: 0 | K35: 0 | L35: 1
F36: 10 | G36: 0 | H36: 0 | I36: 0 | J36: 1 | K36: 0 | L36: 0
F37: 11 | G37: 0 | H37: 0 | I37: 0 | J37: 0 | K37: 0 | L37: 0
F38: 12 | G38: 0 | H38: 0 | I38: 0 | J38: 0 | K38: 0 | L38: 0
F39: 13 | G39: 0 | H39: 0 | I39: 0 | J39: 0 | K39: 0 | L39: 0
... F51: 25 | G51: 0 | H51: 0 | I51: 0 | J51: 0 | K51: 0 | L51: 0
A52: R_Stats_video_Rural_Thermostat | F52: 1 | G52: 0 | H52: 0 | I52: 0 | J52: 0 | K52: 0 | L52: 0
F53: 2 | G53: 0 | H53: 0 | I53: 0 | J53: 0 | K53: 0 | L53: 0
F54: 3 | G54: 0 | H54: 0 | I54: 0 | J54: 0 | K54: 0 | L54: 0
F55: 4 | G55: 0 | H55: 0 | I55: 0 | J55: 0 | K55: 1 | L55: 0
F56: 5 | G56: 0 | H56: 0 | I56: 0 | J56: 0 | K56: 0 | L56: 0
F57: 6 | G57: 0 | H57: 0 | I57: 1 | J57: 0 | K57: 0 | L57: 0
F58: 7 | G58: 0 | H58: 0 | I58: 0 | J58: 0 | K58: 0 | L58: 0
F59: 8 | G59: 0 | H59: 0 | I59: 0 | J59: 0 | K59: 0 | L59: 0
F60: 9 | G60: 0 | H60: 0 | I60: 0 | J60: 0 | K60: 0 | L60: 0
F61: 10 | G61: 0 | H61: 0 | I61: 0 | J61: 1 | K61: 0 | L61: 0
F62: 11 | G62: 0 | H62: 0 | I62: 0 | J62: 1 | K62: 0 | L62: 0
...
